
























<?xml version="1.0" ?>
<!-- DO NOT EDIT: Generated from cloudship.sdf.jinja -->
<sdf version="1.5">

  <model name="cloudship">

    <self_collide>false</self_collide>
    <static>false</static>

    
    <link name="hull">
      <pose>-0.1299999999999999 0 3.1 0 0 0</pose>
      <inertial>
        <pose>0.023862743087597126 0 -0.4953798831128884 0 0 0</pose>
        <mass>7.314749999999999</mass>
        <inertia>
          <ixx>1.7971517083333333</ixx>
          <iyy>4.958383606533334</iyy>
          <izz>7.985372374533334</izz>
        </inertia>
      </inertial>

      <gravity>true</gravity>
      <self_collide>false</self_collide>
      <velocity_decay/>

      
      <visual name="hull_visual">
        <geometry>
          <mesh>
            <scale>2.35 0.8 0.8</scale>
            <uri>model://cloudship/meshes/ellipsoid.stl</uri>
          </mesh>
        </geometry>
      </visual>

      <collision name="hull_collision">
        <pose>0 0 0 0 0 0</pose>
        <geometry>
          <mesh>
            <scale>2.35 0.8 0.8</scale>
            <uri>model://cloudship/meshes/ellipsoid.stl</uri>
          </mesh>
        </geometry>
      </collision>

      
      <visual name="gondola_visual">
        <pose>0.2200000000000002 0 -0.7986 0 0 0</pose>
        <geometry>
          <box>
            <size>0.4 0.17 0.2</size>
          </box>
        </geometry>
      </visual>

      <collision name="gondola_collision">
        <pose>0.2200000000000002 0 -0.8486 0 0 0</pose>
        <geometry>
          <box>
            <size>0.4 0.17 0.1</size>
          </box>
        </geometry>
      </collision>

      
      <visual name="payload_visual">
      <pose>-0.17999999999999972 0 -0.784 1.5707963267948966 0 0</pose>
        <geometry>
          <cylinder>
            <radius>0.05</radius>
            <length>0.1</length>
          </cylinder>
        </geometry>
      </visual>

      <collision name="payload_collision">
      <pose>-0.17999999999999972 0 -0.784 1.5707963267948966 0 0</pose>
        <geometry>
          <cylinder>
            <radius>0.05</radius>
            <length>0.1</length>
          </cylinder>
        </geometry>
      </collision>

      
      <visual name="fin_top_visual">
  <pose>-1.8799999999999994 0 0.3684 0 0 0</pose>
  <geometry>
          <box>
            <size>0.465 0.01 0.78</size>
          </box>
        </geometry>
</visual>

<collision name="fin_top_collision">
  <pose>-1.8799999999999994 0 0.3684 0 0 0</pose>
  <geometry>
          <box>
            <size>0.465 0.01 0.78</size>
          </box>
        </geometry>
</collision>
      <visual name="fin_port_visual">
  <pose>-1.8799999999999994 0.3684 0 -1.5707963267948966 0 0</pose>
  <geometry>
          <box>
            <size>0.465 0.01 0.78</size>
          </box>
        </geometry>
</visual>

<collision name="fin_port_collision">
  <pose>-1.8799999999999994 0.3684 0 -1.5707963267948966 0 0</pose>
  <geometry>
          <box>
            <size>0.465 0.01 0.78</size>
          </box>
        </geometry>
</collision>
      <visual name="fin_sb_visual">
  <pose>-1.8799999999999994 -0.3684 0 1.5707963267948966 0 0</pose>
  <geometry>
          <box>
            <size>0.465 0.01 0.78</size>
          </box>
        </geometry>
</visual>

<collision name="fin_sb_collision">
  <pose>-1.8799999999999994 -0.3684 0 1.5707963267948966 0 0</pose>
  <geometry>
          <box>
            <size>0.465 0.01 0.78</size>
          </box>
        </geometry>
</collision>

      <visual name="fin_bottom_rotor_visual">
        <pose>-1.8799999999999994 0 -0.7584 0 0 0</pose>
        <geometry>
          <mesh>
            <scale>0.465 0.01 0.39</scale>
            <uri>model://cloudship/meshes/fin_prop.stl</uri>
          </mesh>
        </geometry>
      </visual>
      <visual name="fin_bottom_plate_visual">
        <pose>-1.8799999999999994 0 -0.1734 0 0 0</pose>
        <geometry>
          <box>
            <size>0.465 0.01 0.39</size>
          </box>
        </geometry>
      </visual>

      <collision name="fin_bottom_collision">
        <pose>-1.8799999999999994 0 -0.7584 0 0 0</pose>
        <geometry>
          <mesh>
            <scale>0.465 0.01 0.39</scale>
            <uri>model://cloudship/meshes/fin_prop.stl</uri>
          </mesh>
        </geometry>
      </collision>
    </link>

    
    <include>
      <uri>model://gps</uri>
      <pose>0 0 0 0 0 0</pose>
      <name>gps</name>
    </include>
    <joint name='gps_joint' type='fixed'>
      <child>gps::link</child>
      <parent>hull</parent>
    </joint>

    
    <link name="thrusters_rod">
      <pose>0.19000000000000017 0 2.2514000000000003 0 0 0</pose><inertial>
        <mass>0.5</mass>
        <inertia>
          <ixx>0.0337625</ixx>
          <iyy>2.5e-05</iyy>
          <izz>0.0337625</izz>
        </inertia>
      </inertial>

      <gravity>false</gravity>
      <self_collide>false</self_collide>
      <velocity_decay/>

      <visual name="thrusters_rod_visual">
        <pose>0 0 0 1.5707963267948966 0 0</pose>
        <geometry>
          <cylinder>
            <radius>0.01</radius>
            <length>0.9</length>
          </cylinder>
        </geometry>
      </visual>
      <visual name="port_prop_gaurd_visual">
        <pose>0.02 0.45 0 0 1.5707963267948966 0</pose>
        <geometry>
          <mesh>
            <scale>0.18161000000000002 0.18161000000000002 0.02</scale>
            <uri>model://cloudship/meshes/prop_gaurd.stl</uri>
          </mesh>
        </geometry>
      </visual>
      <visual name="sb_prop_gaurd_visual">
        <pose>0.02 -0.45 0 0 1.5707963267948966 0</pose>
        <geometry>
          <mesh>
            <scale>0.18161000000000002 0.18161000000000002 0.02</scale>
            <uri>model://cloudship/meshes/prop_gaurd.stl</uri>
          </mesh>
        </geometry>
      </visual>

      <collision name="thrusters_rod_port_collision">
        <pose>0 0.2675 0 1.5707963267948966 0 0</pose>
        <geometry>
          <cylinder>
            <radius>0.01</radius>
            <length>0.365</length>
          </cylinder>
        </geometry>
      </collision>
      <collision name="thrusters_rod_sb_collision">
        <pose>0 -0.2675 0 1.5707963267948966 0 0</pose>
        <geometry>
          <cylinder>
            <radius>0.01</radius>
            <length>0.365</length>
          </cylinder>
        </geometry>
      </collision>
    </link>

    <joint name='thrusters_rod_joint' type='revolute'>
      <parent>hull</parent>
      <child>thrusters_rod</child>
      <axis>
        <xyz>0 1 0</xyz>
        <limit>
          <lower>-3.141592653589793</lower>
          <upper>3.141592653589793</upper>
        </limit>
        <dynamics>
          <damping>0.1</damping>
        </dynamics>
      </axis>
      <physics>
        <ode>
          <implicit_spring_damper>1</implicit_spring_damper>
        </ode>
      </physics>
    </joint>

    
    <link name="rotor_0">
  <pose>0.2100000000000002 0.45 2.2464 0 1.5707963267948966 0</pose>
  <inertial>
        <mass>0.0025</mass>
        <inertia>
          <ixx>1.0000000000000002e-06</ixx>
          <iyy>2.2798341666666663e-05</iyy>
          <izz>2.2798341666666663e-05</izz>
        </inertia>
      </inertial>

  <gravity>false</gravity>
  <self_collide>false</self_collide>
  <velocity_decay/>

  <visual name="rotor_0_visual">
    <geometry>
      <mesh>
        <scale>1.2842752129438761 1.2842752129438761 2.0855057351407718</scale>
        <uri>model://cloudship/meshes/prop_ccw.dae</uri>
      </mesh>
    </geometry>
  </visual>

  <collision name="rotor_0_collision">
    <geometry>
      <cylinder>
        <length>0.02</length>
        <radius>0.1651</radius>
      </cylinder>
    </geometry>
  </collision>
</link>

<joint name='rotor_0_joint' type='revolute'>
  <child>rotor_0</child>
  <parent>thrusters_rod</parent>
  <axis>
    <xyz>0 0 1</xyz>
    <limit>
      <lower>-1e+16</lower>
      <upper>1e+16</upper>
    </limit>
    <dynamics>
      <spring_reference>0</spring_reference>
      <spring_stiffness>0</spring_stiffness>
    </dynamics>
  </axis>
</joint>


<plugin name='rotor_0_model' filename='libgazebo_motor_model.so'>
  <robotNamespace/>
  <jointName>rotor_0_joint</jointName>
  <linkName>rotor_0</linkName>
  <turningDirection>ccw</turningDirection>
  <reversible>False</reversible>
  <timeConstantUp>0.05</timeConstantUp>
  <timeConstantDown>0.05</timeConstantDown>
  <maxRotVelocity>1500</maxRotVelocity>
  <motorConstant>7.063200000000001e-06</motorConstant>
  <momentConstant>0</momentConstant>
  <rotorDragCoefficient>0.000806428</rotorDragCoefficient>
  <rollingMomentCoefficient>1e-06</rollingMomentCoefficient>
  <commandSubTopic>/gazebo/command/motor_speed</commandSubTopic>
  <motorNumber>0</motorNumber>
  <motorSpeedPubTopic>/motor_speed/0</motorSpeedPubTopic>
  <rotorVelocitySlowdownSim>10</rotorVelocitySlowdownSim>
</plugin>
    <link name="rotor_1">
  <pose>0.2100000000000002 -0.45 2.2514000000000003 0 1.5707963267948966 0</pose>
  <inertial>
        <mass>0.0025</mass>
        <inertia>
          <ixx>1.0000000000000002e-06</ixx>
          <iyy>2.2798341666666663e-05</iyy>
          <izz>2.2798341666666663e-05</izz>
        </inertia>
      </inertial>

  <gravity>false</gravity>
  <self_collide>false</self_collide>
  <velocity_decay/>

  <visual name="rotor_1_visual">
    <geometry>
      <mesh>
        <scale>1.2842752129438761 1.2842752129438761 2.0855057351407718</scale>
        <uri>model://cloudship/meshes/prop_cw.dae</uri>
      </mesh>
    </geometry>
  </visual>

  <collision name="rotor_1_collision">
    <geometry>
      <cylinder>
        <length>0.02</length>
        <radius>0.1651</radius>
      </cylinder>
    </geometry>
  </collision>
</link>

<joint name='rotor_1_joint' type='revolute'>
  <child>rotor_1</child>
  <parent>thrusters_rod</parent>
  <axis>
    <xyz>0 0 1</xyz>
    <limit>
      <lower>-1e+16</lower>
      <upper>1e+16</upper>
    </limit>
    <dynamics>
      <spring_reference>0</spring_reference>
      <spring_stiffness>0</spring_stiffness>
    </dynamics>
  </axis>
</joint>


<plugin name='rotor_1_model' filename='libgazebo_motor_model.so'>
  <robotNamespace/>
  <jointName>rotor_1_joint</jointName>
  <linkName>rotor_1</linkName>
  <turningDirection>cw</turningDirection>
  <reversible>False</reversible>
  <timeConstantUp>0.05</timeConstantUp>
  <timeConstantDown>0.05</timeConstantDown>
  <maxRotVelocity>1500</maxRotVelocity>
  <motorConstant>7.063200000000001e-06</motorConstant>
  <momentConstant>0</momentConstant>
  <rotorDragCoefficient>0.000806428</rotorDragCoefficient>
  <rollingMomentCoefficient>1e-06</rollingMomentCoefficient>
  <commandSubTopic>/gazebo/command/motor_speed</commandSubTopic>
  <motorNumber>1</motorNumber>
  <motorSpeedPubTopic>/motor_speed/1</motorSpeedPubTopic>
  <rotorVelocitySlowdownSim>10</rotorVelocitySlowdownSim>
</plugin>
    <link name="rotor_3">
  <pose>-2.0099999999999993 0 2.5366 1.5707963267948966 0 0</pose>
  <inertial>
        <mass>0.0015</mass>
        <inertia>
          <ixx>6.000000000000001e-07</ixx>
          <iyy>2.0661250000000005e-06</iyy>
          <izz>2.0661250000000005e-06</izz>
        </inertia>
      </inertial>

  <gravity>false</gravity>
  <self_collide>false</self_collide>
  <velocity_decay/>

  <visual name="rotor_3_visual">
    <geometry>
      <mesh>
        <scale>0.4939520049784139 0.4939520049784139 2.0855057351407718</scale>
        <uri>model://cloudship/meshes/prop_cw.dae</uri>
      </mesh>
    </geometry>
  </visual>

  <collision name="rotor_3_collision">
    <geometry>
      <cylinder>
        <length>0.02</length>
        <radius>0.0635</radius>
      </cylinder>
    </geometry>
  </collision>
</link>

<joint name='rotor_3_joint' type='revolute'>
  <child>rotor_3</child>
  <parent>hull</parent>
  <axis>
    <xyz>0 0 1</xyz>
    <limit>
      <lower>-1e+16</lower>
      <upper>1e+16</upper>
    </limit>
    <dynamics>
      <spring_reference>0</spring_reference>
      <spring_stiffness>0</spring_stiffness>
    </dynamics>
  </axis>
</joint>


<plugin name='rotor_3_model' filename='libgazebo_motor_model.so'>
  <robotNamespace/>
  <jointName>rotor_3_joint</jointName>
  <linkName>rotor_3</linkName>
  <turningDirection>cw</turningDirection>
  <reversible>True</reversible>
  <timeConstantUp>0.025</timeConstantUp>
  <timeConstantDown>0.025</timeConstantDown>
  <maxRotVelocity>1500</maxRotVelocity>
  <motorConstant>1.0464e-06</motorConstant>
  <momentConstant>0</momentConstant>
  <rotorDragCoefficient>0.000806428</rotorDragCoefficient>
  <rollingMomentCoefficient>1e-06</rollingMomentCoefficient>
  <commandSubTopic>/gazebo/command/motor_speed</commandSubTopic>
  <motorNumber>3</motorNumber>
  <motorSpeedPubTopic>/motor_speed/3</motorSpeedPubTopic>
  <rotorVelocitySlowdownSim>10</rotorVelocitySlowdownSim>
</plugin>

    
    
    <plugin name='gazebo_airship_dynamics_plugin' filename='libgazebo_airship_dynamics_plugin.so'>
      <robotNamespace/>
      <linkName>hull</linkName>
      <hullVolume>5.97</hullVolume>
      <airDensity>1.225</airDensity>
      <m11>0.34094584</m11>
      <m22>6.89645916</m22>
      <m26>0.8003539</m26>
      <m33>6.89645916</m33>
      <m35>-0.8003539</m35>
      <m44>0.03909877</m44>
      <m53>-0.8003539</m53>
      <m55>4.51385307</m55>
      <m62>0.8003539</m62>
      <m66>4.51385307</m66>
      <distCOV>2.22</distCOV>
      <distPotentialFlow>3.758</distPotentialFlow>
      <distFinCenter>3.884</distFinCenter>
      <distQuarterChord>0.7454</distQuarterChord>
      <forceHullInviscidFlowCoeff>-0.9576310423950283</forceHullInviscidFlowCoeff>
      <forceHullViscousFlowCoeff>0.5829522229750153</forceHullViscousFlowCoeff>
      <momentHullInviscidFlowCoeff>1.9534480725890846</momentHullInviscidFlowCoeff>
      <momentHullViscousFlowCoeff>-1.1196943420983705</momentHullViscousFlowCoeff>
      <finNormalForceCoeff>0.552208563394833</finNormalForceCoeff>
      <finStallAngle>19.098</finStallAngle>
      <axialDragCoeff>0.35</axialDragCoeff>
      <windSubTopic>/wind_vel</windSubTopic>
    </plugin>

    
    <include>
      <uri>model://imu</uri>
      <pose>0 0 0 0 0 0</pose>
      <name>imu</name>
    </include>
    <joint name='imu_joint' type='fixed'>
      <child>imu::link</child>
      <parent>hull</parent>
    </joint>

    
    <include>
      <uri>model://magnetometer</uri>
      <pose>0 0 0 0 0 0</pose>
      <name>mag</name>
    </include>
    <joint name='mag_joint' type='fixed'>
      <child>mag::link</child>
      <parent>hull</parent>
    </joint>

    
    <plugin name='barometer_plugin' filename='libgazebo_barometer_plugin.so'>
      <robotNamespace/>
      <pubRate>10</pubRate>
      <baroTopic>/baro</baroTopic>
    </plugin>

    
    <plugin name='mavlink_interface' filename='libgazebo_mavlink_interface.so'>
      <robotNamespace/>
      <imuSubTopic>/imu</imuSubTopic>
      <gpsSubTopic>/gps</gpsSubTopic>
      <magSubTopic>/mag</magSubTopic>
      <baroSubTopic>/baro</baroSubTopic>

      <mavlink_addr>INADDR_ANY</mavlink_addr>
      <mavlink_udp_port>14560</mavlink_udp_port>
      <mavlink_tcp_port>4560</mavlink_tcp_port>
      <serialEnabled>false</serialEnabled>
      <serialDevice>/dev/ttyACM0</serialDevice>
      <baudRate>921600</baudRate>
      <qgc_addr>INADDR_ANY</qgc_addr>
      <qgc_udp_port>14550</qgc_udp_port>

      <hil_mode>false</hil_mode>
      <hil_state_level>false</hil_state_level>
      <enable_lockstep>true</enable_lockstep>
      <use_tcp>true</use_tcp>

      <send_vision_estimation>true</send_vision_estimation>
      <send_odometry>false</send_odometry>

      <control_channels>
        <channel name='rotor_1'>
          <input_index>0</input_index>
          <input_offset>0</input_offset>
          <input_scaling>1500</input_scaling>
          <zero_position_disarmed>0</zero_position_disarmed>
          <zero_position_armed>0</zero_position_armed>
          <joint_control_type>velocity</joint_control_type>
          <joint_name>rotor_1_joint</joint_name>
        </channel>
        <channel name='rotor_2'>
          <input_index>1</input_index>
          <input_offset>0</input_offset>
          <input_scaling>1500</input_scaling>
          <zero_position_disarmed>0</zero_position_disarmed>
          <zero_position_armed>0</zero_position_armed>
          <joint_control_type>velocity</joint_control_type>
          <joint_name>rotor_2_joint</joint_name>
        </channel>
        <channel name="thrusters_rod">
          <input_index>2</input_index>
          <input_offset>0</input_offset>
          <input_scaling>-2.356194490192345</input_scaling>
          <zero_position_disarmed>0</zero_position_disarmed>
          <zero_position_armed>0</zero_position_armed>
          <joint_control_type>position</joint_control_type>
          <joint_control_pid>
            <p>80</p>
            <i>0</i>
            <d>0</d>
            <iMax>0.0</iMax>
            <iMin>0.0</iMin>
            <cmdMax>1.1780972450961724</cmdMax>
            <cmdMin>-1.1780972450961724</cmdMin>
          </joint_control_pid>
          <joint_name>thrusters_rod_joint</joint_name>
        </channel>
        <channel name='rotor_3'>
          <input_index>3</input_index>
          <input_offset>0</input_offset>
          <input_scaling>1500</input_scaling>
          <zero_position_disarmed>0</zero_position_disarmed>
          <zero_position_armed>0</zero_position_armed>
          <joint_control_type>velocity</joint_control_type>
          <joint_name>rotor_3_joint</joint_name>
        </channel>
      </control_channels>
    </plugin>

  </model>

</sdf>

<!-- vim: set et ft=xml fenc=utf-8 ff=unix sts=0 sw=2 ts=2 : -->